2024-01-23 21:05:01,438 ERROR Internal Server Error: / C:\Users\user\PycharmProjects\pythonProject14\venv\lib\site-packages\django\utils\log.py (<class 'NameError'>, NameError("name 'contexts' is not defined"), <traceback object at 0x000001C3030FF900>)
Traceback (most recent call last):
  File "C:\Users\user\PycharmProjects\pythonProject14\venv\lib\site-packages\django\core\handlers\exception.py", line 55, in inner
    response = get_response(request)
  File "C:\Users\user\PycharmProjects\pythonProject14\venv\lib\site-packages\django\core\handlers\base.py", line 197, in _get_response
    response = wrapped_callback(request, *callback_args, **callback_kwargs)
  File "C:\Users\user\PycharmProjects\pythonProject14\venv\lib\site-packages\django\views\generic\base.py", line 104, in view
    return self.dispatch(request, *args, **kwargs)
  File "C:\Users\user\PycharmProjects\pythonProject14\venv\lib\site-packages\django\views\generic\base.py", line 143, in dispatch
    return handler(request, *args, **kwargs)
  File "C:\Users\user\PycharmProjects\pythonProject14\venv\lib\site-packages\django\views\generic\base.py", line 226, in get
    context = self.get_context_data(**kwargs)
  File "C:\Users\user\PycharmProjects\pythonProject14\project\simpleapp\views.py", line 13, in get_context_data
    return contexts
NameError: name 'contexts' is not defined
2024-01-23 21:05:01,438 ERROR Internal Server Error: / C:\Users\user\PycharmProjects\pythonProject14\venv\lib\site-packages\django\utils\log.py (<class 'NameError'>, NameError("name 'contexts' is not defined"), <traceback object at 0x000001C3030FF900>)
Traceback (most recent call last):
  File "C:\Users\user\PycharmProjects\pythonProject14\venv\lib\site-packages\django\core\handlers\exception.py", line 55, in inner
    response = get_response(request)
  File "C:\Users\user\PycharmProjects\pythonProject14\venv\lib\site-packages\django\core\handlers\base.py", line 197, in _get_response
    response = wrapped_callback(request, *callback_args, **callback_kwargs)
  File "C:\Users\user\PycharmProjects\pythonProject14\venv\lib\site-packages\django\views\generic\base.py", line 104, in view
    return self.dispatch(request, *args, **kwargs)
  File "C:\Users\user\PycharmProjects\pythonProject14\venv\lib\site-packages\django\views\generic\base.py", line 143, in dispatch
    return handler(request, *args, **kwargs)
  File "C:\Users\user\PycharmProjects\pythonProject14\venv\lib\site-packages\django\views\generic\base.py", line 226, in get
    context = self.get_context_data(**kwargs)
  File "C:\Users\user\PycharmProjects\pythonProject14\project\simpleapp\views.py", line 13, in get_context_data
    return contexts
NameError: name 'contexts' is not defined
2024-01-23 21:05:01,454 ERROR "GET / HTTP/1.1" 500 80731 C:\Users\user\PycharmProjects\pythonProject14\venv\lib\site-packages\django\core\servers\basehttp.py None
